2024-09-29 19:33:15,182 - INFO - Démarrage de l'exécution
2024-09-29 19:33:15,182 - INFO - Chargement du modèle depuis ../src/stylegan3-t-ffhq-1024x1024.pkl...
2024-09-29 19:33:20,087 - INFO - Modèle chargé avec succès.
2024-09-29 19:33:20,088 - INFO - ImageGenerator initialisé avec succès.
2024-09-29 19:33:20,088 - INFO - Chargement de l'image depuis : ../data/test_enfant.png
2024-09-29 19:33:20,122 - INFO - Image redimensionnée à 1024x1024.
2024-09-29 19:33:20,177 - INFO - Image transformée et prête pour la génération.
2024-09-29 19:33:21,742 - INFO - Optimisation à la résolution 64x64
2024-09-29 19:33:21,742 - ERROR - Une erreur est survenue
2024-09-29 19:33:21,742 - ERROR - Détails de l'exception : 
Traceback (most recent call last):
  File "/notebooks/scripts/main.py", line 71, in main
    generator.project_with_progressive_growing()
  File "/notebooks/scripts/ImageGenerator.py", line 167, in project_with_progressive_growing
    target_image = self.model.synthesis(original_image, noise_mode='const', force_fp32=True)
                   ^^^^^^^^^^^^^^^^^^^^^^^^^^^^^^^^^^^^^^^^^^^^^^^^^^^^^^^^^^^^^^^^^^^^^^^^^
  File "/usr/local/lib/python3.11/dist-packages/torch/nn/modules/module.py", line 1518, in _wrapped_call_impl
    return self._call_impl(*args, **kwargs)
           ^^^^^^^^^^^^^^^^^^^^^^^^^^^^^^^^
  File "/usr/local/lib/python3.11/dist-packages/torch/nn/modules/module.py", line 1527, in _call_impl
    return forward_call(*args, **kwargs)
           ^^^^^^^^^^^^^^^^^^^^^^^^^^^^^
  File "<string>", line 457, in forward
  File "/notebooks/scripts/../src/stylegan3/torch_utils/misc.py", line 84, in assert_shape
    raise AssertionError(f'Wrong number of dimensions: got {tensor.ndim}, expected {len(ref_shape)}')
AssertionError: Wrong number of dimensions: got 4, expected 3
